Workbook

Sheet Read Me
B2: GET LUCKY GOLF CLUB — PRO FORMA
B3: Three-part revenue model: membership, pay-per-play, upsells.
B5: HOW THE MODEL WORKS
B6: Membership buys ACCESS — the app, the courses, member pricing. It carries no prize risk and insures nothing.
B7: The ENTRY buys one swing at one insured prize. 24% of it is ceded as premium on that same swing.
B8: UPSELLS are added in the moment, on top of an entry. They attach to entries already counted — never new volume.
B9: This structure is why the cover is underwritable. A subscription buying unlimited insured swings leaves premium fixed
B10: and exposure open-ended. Charging for the swing closes it. See the Insurance tab and GetLucky_Insurance_Model.xlsx.
B12: REPORTING BASIS
B13: Every stream is reported NET of third-party shares so they sit on one basis and can be added:
B14: membership 100% | pay-per-play 66% (24% insurer + 10% course removed) | upsells 55%
B15: simulators 46% (24% insurer + 30% operator removed) | sponsorship 100%
... B34: South African sponsorship is held FLAT at the contracted R3.5m run-rate after the Santam deal expires in 2028.

Sheet Assumptions
B2: ASSUMPTIONS
B3: Blue = change me. Black = calculated.
B5: DEAL
B6: ZAR per USD | C6: 18.5 | D6: FX assumption
B7: Raise (ZAR) | C7: 8000000 | D7: This round
B8: Equity offered | C8: 0.15 | D8: 15%
B9: Post-money (ZAR) | C9: =C7/C8 | D9: Exact: 8.0m / 15%
B11: MEMBERS
B12: Members at month 0 (CONVERSION TARGET) | C12: 2000 | D12: NOT a current paying base — converted from the 60,000 reached, ramped over 6 months
B13: Conversion ramp (months) | C13: 6 | D13: The 2,000 arrives over this many months
B14: Gross monthly growth — Year 1 | C14: 0.105 | D14: The Ernie effect
B15: Gross monthly growth — Year 2 | C15: 0.08 | D15: SA + first international
B16: Gross monthly growth — Year 3 | C16: 0.07 | D16: Global markets open
B17: Gross monthly growth — Year 4+ | C17: 0.058 | D17: 1.8% net + 4% churn
B18: Monthly churn | C18: 0.04 | D18: % of base lost per month
B19: Membership price (USD/month) | C19: 10 | D19: Access only. No prize risk.
B21: PAY-PER-PLAY
B22: Rounds per member per month | C22: 4 | D22: Rounds of golf played
B23: Par 3 holes per round | C23: 4 | D23: One shot at each
B24: Par 3 attempts per member per month | C24: =C22*C23 | D24: Maximum insurable swings available
B25: Entry conversion (% of attempts bought) | C25: 0.0625 | D25: In-app take-up on an available Par 3
B26: Paid entries per member per month | C26: =C24*C25 | D26: Drives all revenue AND all exposure
B27: Weighted average entry (USD) | C27: 17 | D27: From the tier mix on the Insurance tab
B28: Insurance premium (% of entry) | C28: 0.24 | D28: Ceded to the underwriter on the same swing
B29: Course share (% of entry) | C29: 0.1 | D29: Course pays nothing upfront
B30: Get Lucky share of entry | C30: =1-C28-C29 | D30: 66%
B32: UPSELLS
B33: Attach rate on paid entries | C33: 0.09 | D33: Modelled, not observed — menu ships 2027
B34: Average upsell (USD) | C34: 5
B35: Get Lucky net share | C35: 0.55
B37: COST STACK
B38: Payment processing (% of gross collections) | C38: 0.03
B39: Verification & claims ops (USD per paid entry) | C39: 0.5 | D39: Someone must verify every claim
B40: Acquisition — CAC (USD per gross new member) | C40: 12
B41: Brand & retention (% of revenue) | C41: 0.08
B42: Central budget 2026 (ZAR) | C42: 9500000 | D42: STATED BUDGET — hires ahead of revenue, not a % of revenue
B43: Central budget 2029 (ZAR) | C43: 38000000
B44: Central budget 2032 (ZAR) | C44: 72000000
B46: VALUATION
B47: Revenue multiple — every forward milestone | C47: 3 | D47: Flat. No expansion assumed anywhere.
...

Sheet Build (Monthly)
B2: 84-MONTH BUILD — Jan 2026 to Dec 2032
B3: Milestone is month 48 (Dec 2029). Calendar-year totals on the Annual tab.
B5: Month | C5: 1 | D5: 2 | E5: 3 | F5: 4 | G5: 5 | H5: 6 | I5: 7 | J5: 8 | K5: 9 | L5: 10 | M5: 11 | N5: 12 | O5: 13 | P5: 14 | Q5: 15 | R5: 16 | S5: 17 | T5: 18 | U5: 19 | V5: 20 | W5: 21 | X5: 22 | Y5: 23 | Z5: 24 | AA5: 25 | AB5: 26 | AC5: 27 | AD5: 28 | AE5: 29 | AF5: 30 | AG5: 31 | AH5: 32 | AI5: 33 | AJ5: 34 | AK5: 35 | AL5: 36 | AM5: 37 | AN5: 38 | AO5: 39 | AP5: 40 | AQ5: 41 | AR5: 42 | AS5: 43 | AT5: 44 | AU5: 45 | AV5: 46 | AW5: 47 | AX5: 48 | AY5: 49 | AZ5: 50 | BA5: 51 | BB5: 52 | BC5: 53 | BD5: 54 | BE5: 55 | BF5: 56 | BG5: 57 | BH5: 58 | BI5: 59 | BJ5: 60 | BK5: 61 | BL5: 62 | BM5: 63 | BN5: 64 | BO5: 65 | BP5: 66 | BQ5: 67 | BR5: 68 | BS5: 69 | BT5: 70 | BU5: 71 | BV5: 72 | BW5: 73 | BX5: 74 | BY5: 75 | BZ5: 76 | CA5: 77 | CB5: 78 | CC5: 79 | CD5: 80 | CE5: 81 | CF5: 82 | CG5: 83 | CH5: 84
B6: Calendar year | C6: 2026 | D6: 2026 | E6: 2026 | F6: 2026 | G6: 2026 | H6: 2026 | I6: 2026 | J6: 2026 | K6: 2026 | L6: 2026 | M6: 2026 | N6: 2026 | O6: 2027 | P6: 2027 | Q6: 2027 | R6: 2027 | S6: 2027 | T6: 2027 | U6: 2027 | V6: 2027 | W6: 2027 | X6: 2027 | Y6: 2027 | Z6: 2027 | AA6: 2028 | AB6: 2028 | AC6: 2028 | AD6: 2028 | AE6: 2028 | AF6: 2028 | AG6: 2028 | AH6: 2028 | AI6: 2028 | AJ6: 2028 | AK6: 2028 | AL6: 2028 | AM6: 2029 | AN6: 2029 | AO6: 2029 | AP6: 2029 | AQ6: 2029 | AR6: 2029 | AS6: 2029 | AT6: 2029 | AU6: 2029 | AV6: 2029 | AW6: 2029 | AX6: 2029 | AY6: 2030 | AZ6: 2030 | BA6: 2030 | BB6: 2030 | BC6: 2030 | BD6: 2030 | BE6: 2030 | BF6: 2030 | BG6: 2030 | BH6: 2030 | BI6: 2030 | BJ6: 2030 | BK6: 2031 | BL6: 2031 | BM6: 2031 | BN6: 2031 | BO6: 2031 | BP6: 2031 | BQ6: 2031 | BR6: 2031 | BS6: 2031 | BT6: 2031 | BU6: 2031 | BV6: 2031 | BW6: 2032 | BX6: 2032 | BY6: 2032 | BZ6: 2032 | CA6: 2032 | CB6: 2032 | CC6: 2032 | CD6: 2032 | CE6: 2032 | CF6: 2032 | CG6: 2032 | CH6: 2032
B7: Year index | C7: 1 | D7: 1 | E7: 1 | F7: 1 | G7: 1 | H7: 1 | I7: 1 | J7: 1 | K7: 1 | L7: 1 | M7: 1 | N7: 1 | O7: 2 | P7: 2 | Q7: 2 | R7: 2 | S7: 2 | T7: 2 | U7: 2 | V7: 2 | W7: 2 | X7: 2 | Y7: 2 | Z7: 2 | AA7: 3 | AB7: 3 | AC7: 3 | AD7: 3 | AE7: 3 | AF7: 3 | AG7: 3 | AH7: 3 | AI7: 3 | AJ7: 3 | AK7: 3 | AL7: 3 | AM7: 4 | AN7: 4 | AO7: 4 | AP7: 4 | AQ7: 4 | AR7: 4 | AS7: 4 | AT7: 4 | AU7: 4 | AV7: 4 | AW7: 4 | AX7: 4 | AY7: 5 | AZ7: 5 | BA7: 5 | BB7: 5 | BC7: 5 | BD7: 5 | BE7: 5 | BF7: 5 | BG7: 5 | BH7: 5 | BI7: 5 | BJ7: 5 | BK7: 6 | BL7: 6 | BM7: 6 | BN7: 6 | BO7: 6 | BP7: 6 | BQ7: 6 | BR7: 6 | BS7: 6 | BT7: 6 | BU7: 6 | BV7: 6 | BW7: 7 | BX7: 7 | BY7: 7 | BZ7: 7 | CA7: 7 | CB7: 7 | CC7: 7 | CD7: 7 | CE7: 7 | CF7: 7 | CG7: 7 | CH7: 7
B8: Gross growth rate applied | C8: =Assumptions!$C$14 | D8: =Assumptions!$C$14 | E8: =Assumptions!$C$14 | F8: =Assumptions!$C$14 | G8: =Assumptions!$C$14 | H8: =Assumptions!$C$14 | I8: =Assumptions!$C$14 | J8: =Assumptions!$C$14 | ... N8: =Assumptions!$C$14 | O8: =Assumptions!$C$15 | P8: =Assumptions!$C$15 | Q8: =Assumptions!$C$15 | R8: =Assumptions!$C$15 | S8: =Assumptions!$C$15 | T8: =Assumptions!$C$15 | U8: =Assumptions!$C$15 | V8: =Assumptions!$C$15 | ... Z8: =Assumptions!$C$15 | AA8: =Assumptions!$C$16 | AB8: =Assumptions!$C$16 | AC8: =Assumptions!$C$16 | AD8: =Assumptions!$C$16 | AE8: =Assumptions!$C$16 | AF8: =Assumptions!$C$16 | AG8: =Assumptions!$C$16 | AH8: =Assumptions!$C$16 | ... AL8: =Assumptions!$C$16 | AM8: =Assumptions!$C$17 | AN8: =Assumptions!$C$17 | AO8: =Assumptions!$C$17 | AP8: =Assumptions!$C$17 | AQ8: =Assumptions!$C$17 | AR8: =Assumptions!$C$17 | AS8: =Assumptions!$C$17 | AT8: =Assumptions!$C$17 | ... CH8: =Assumptions!$C$17
B10: MEMBERS
B11: Opening members | C11: 0 | D11: =C15 | E11: =D15 | F11: =E15 | G11: =F15 | H11: =G15 | I11: =H15 | J11: =I15 | K11: =J15 | ... CH11: =CG15
B12: Conversion intake (ramp) | C12: =IF(C5<=Assumptions!$C$13,Assumptions!$C$12/Assumptions!$C$13,0) | D12: =IF(D5<=Assumptions!$C$13,Assumptions!$C$12/Assumptions!$C$13,0) | E12: =IF(E5<=Assumptions!$C$13,Assumptions!$C$12/Assumptions!$C$13,0) | F12: =IF(F5<=Assumptions!$C$13,Assumptions!$C$12/Assumptions!$C$13,0) | G12: =IF(G5<=Assumptions!$C$13,Assumptions!$C$12/Assumptions!$C$13,0) | H12: =IF(H5<=Assumptions!$C$13,Assumptions!$C$12/Assumptions!$C$13,0) | I12: =IF(I5<=Assumptions!$C$13,Assumptions!$C$12/Assumptions!$C$13,0) | J12: =IF(J5<=Assumptions!$C$13,Assumptions!$C$12/Assumptions!$C$13,0) | ... CH12: =IF(CH5<=Assumptions!$C$13,Assumptions!$C$12/Assumptions!$C$13,0)
B13: Organic new | C13: =C11*C8 | D13: =D11*D8 | E13: =E11*E8 | F13: =F11*F8 | G13: =G11*G8 | H13: =H11*H8 | I13: =I11*I8 | J13: =J11*J8 | ... CH13: =CH11*CH8
B14: Churned | C14: =-C11*Assumptions!$C$18 | D14: =-D11*Assumptions!$C$18 | E14: =-E11*Assumptions!$C$18 | F14: =-F11*Assumptions!$C$18 | G14: =-G11*Assumptions!$C$18 | H14: =-H11*Assumptions!$C$18 | I14: =-I11*Assumptions!$C$18 | J14: =-J11*Assumptions!$C$18 | ... CH14: =-CH11*Assumptions!$C$18
B15: Closing members | C15: =C11+C12+C13+C14 | D15: =D11+D12+D13+D14 | E15: =E11+E12+E13+E14 | F15: =F11+F12+F13+F14 | G15: =G11+G12+G13+G14 | H15: =H11+H12+H13+H14 | I15: =I11+I12+I13+I14 | J15: =J11+J12+J13+J14 | ... CH15: =CH11+CH12+CH13+CH14
B16: Average active members | C16: =AVERAGE(C11,C15) | D16: =AVERAGE(D11,D15) | E16: =AVERAGE(E11,E15) | F16: =AVERAGE(F11,F15) | G16: =AVERAGE(G11,G15) | H16: =AVERAGE(H11,H15) | I16: =AVERAGE(I11,I15) | J16: =AVERAGE(J11,J15) | ... CH16: =AVERAGE(CH11,CH15)
B18: PAY-PER-PLAY
B19: Par 3 attempts available | C19: =C16*Assumptions!$C$24 | D19: =D16*Assumptions!$C$24 | E19: =E16*Assumptions!$C$24 | F19: =F16*Assumptions!$C$24 | G19: =G16*Assumptions!$C$24 | H19: =H16*Assumptions!$C$24 | I19: =I16*Assumptions!$C$24 | J19: =J16*Assumptions!$C$24 | ... CH19: =CH16*Assumptions!$C$24
B20: Paid entries | C20: =C19*Assumptions!$C$25 | D20: =D19*Assumptions!$C$25 | E20: =E19*Assumptions!$C$25 | F20: =F19*Assumptions!$C$25 | G20: =G19*Assumptions!$C$25 | H20: =H19*Assumptions!$C$25 | I20: =I19*Assumptions!$C$25 | J20: =J19*Assumptions!$C$25 | ... CH20: =CH19*Assumptions!$C$25
B21: Gross entry value ($) | C21: =C20*Assumptions!$C$27 | D21: =D20*Assumptions!$C$27 | E21: =E20*Assumptions!$C$27 | F21: =F20*Assumptions!$C$27 | G21: =G20*Assumptions!$C$27 | H21: =H20*Assumptions!$C$27 | I21: =I20*Assumptions!$C$27 | J21: =J20*Assumptions!$C$27 | ... CH21: =CH20*Assumptions!$C$27
B22: Premium ceded to insurer ($) | C22: =C21*Assumptions!$C$28 | D22: =D21*Assumptions!$C$28 | E22: =E21*Assumptions!$C$28 | F22: =F21*Assumptions!$C$28 | G22: =G21*Assumptions!$C$28 | H22: =H21*Assumptions!$C$28 | I22: =I21*Assumptions!$C$28 | J22: =J21*Assumptions!$C$28 | ... CH22: =CH21*Assumptions!$C$28
B23: Course share ($) | C23: =C21*Assumptions!$C$29 | D23: =D21*Assumptions!$C$29 | E23: =E21*Assumptions!$C$29 | F23: =F21*Assumptions!$C$29 | G23: =G21*Assumptions!$C$29 | H23: =H21*Assumptions!$C$29 | I23: =I21*Assumptions!$C$29 | J23: =J21*Assumptions!$C$29 | ... CH23: =CH21*Assumptions!$C$29
B24: Net entry revenue to Get Lucky ($) | C24: =C21*Assumptions!$C$30 | D24: =D21*Assumptions!$C$30 | E24: =E21*Assumptions!$C$30 | F24: =F21*Assumptions!$C$30 | G24: =G21*Assumptions!$C$30 | H24: =H21*Assumptions!$C$30 | I24: =I21*Assumptions!$C$30 | J24: =J21*Assumptions!$C$30 | ... CH24: =CH21*Assumptions!$C$30
B26: REVENUE ($)
B27: Membership | C27: =C16*Assumptions!$C$19 | D27: =D16*Assumptions!$C$19 | E27: =E16*Assumptions!$C$19 | F27: =F16*Assumptions!$C$19 | G27: =G16*Assumptions!$C$19 | H27: =H16*Assumptions!$C$19 | I27: =I16*Assumptions!$C$19 | J27: =J16*Assumptions!$C$19 | ... CH27: =CH16*Assumptions!$C$19
B28: Pay-per-play (net) | C28: =C24 | D28: =D24 | E28: =E24 | F28: =F24 | G28: =G24 | H28: =H24 | I28: =I24 | J28: =J24 | ... CH28: =CH24
B29: In-play upsells (net) | C29: =C20*Assumptions!$C$33*Assumptions!$C$34*Assumptions!$C$35 | D29: =D20*Assumptions!$C$33*Assumptions!$C$34*Assumptions!$C$35 | E29: =E20*Assumptions!$C$33*Assumptions!$C$34*Assumptions!$C$35 | F29: =F20*Assumptions!$C$33*Assumptions!$C$34*Assumptions!$C$35 | G29: =G20*Assumptions!$C$33*Assumptions!$C$34*Assumptions!$C$35 | H29: =H20*Assumptions!$C$33*Assumptions!$C$34*Assumptions!$C$35 | I29: =I20*Assumptions!$C$33*Assumptions!$C$34*Assumptions!$C$35 | J29: =J20*Assumptions!$C$33*Assumptions!$C$34*Assumptions!$C$35 | ... CH29: =CH20*Assumptions!$C$33*Assumptions!$C$34*Assumptions!$C$35
B31: MEMO — INSURANCE
B32: Expected aces | C32: =C20*Insurance!$C$8 | D32: =D20*Insurance!$C$8 | E32: =E20*Insurance!$C$8 | F32: =F20*Insurance!$C$8 | G32: =G20*Insurance!$C$8 | H32: =H20*Insurance!$C$8 | I32: =I20*Insurance!$C$8 | J32: =J20*Insurance!$C$8 | ... CH32: =CH20*Insurance!$C$8
B33: Expected claims ($) | C33: =C20*Insurance!$C$28 | D33: =D20*Insurance!$C$28 | E33: =E20*Insurance!$C$28 | F33: =F20*Insurance!$C$28 | G33: =G20*Insurance!$C$28 | H33: =H20*Insurance!$C$28 | I33: =I20*Insurance!$C$28 | J33: =J20*Insurance!$C$28 | ... CH33: =CH20*Insurance!$C$28

Sheet Insurance
B2: INSURANCE — WHY THE COVER WORKS
B3: Premium is collected on the same swing that creates the risk. Source: GetLucky_Insurance_Model.xlsx (Santam submission).
B5: Premium (% of entry) | C5: 0.24
B6: Cover (% of prize) | C6: 1
B7: Broker commission to Indwe (% of premium) | C7: 0.2
B8: Per-attempt ace probability | C8: 8e-05
B9: Implied odds — 1 in X | C9: =1/C8
B11: TIER LADDER
B12: Tier | C12: Entry ($) | D12: Prize ($) | E12: Mix | F12: Premium/entry | G12: Exp. claim/entry | H12: Loss ratio
B13: Tier 1 | C13: 1 | D13: 500 | E13: 0.25 | F13: =C13*$C$5 | G13: =D13*$C$8*$C$6 | H13: =G13/F13
B14: Tier 2 | C14: 5 | D14: 2500 | E14: 0.25 | F14: =C14*$C$5 | G14: =D14*$C$8*$C$6 | H14: =G14/F14
B15: Tier 3 | C15: 10 | D15: 10000 | E15: 0.3 | F15: =C15*$C$5 | G15: =D15*$C$8*$C$6 | H15: =G15/F15
B16: Tier 4 | C16: 50 | D16: 50000 | E16: 0.15 | F16: =C16*$C$5 | G16: =D16*$C$8*$C$6 | H16: =G16/F16
B17: Tier 5 | C17: 100 | D17: 100000 | E17: 0.05 | F17: =C17*$C$5 | G17: =D17*$C$8*$C$6 | H17: =G17/F17
B18: Weighted average | C18: =SUMPRODUCT($E$13:$E$17,C13:C17) | D18: =SUMPRODUCT($E$13:$E$17,D13:D17) | E18: =SUM(E13:E17) | F18: =SUMPRODUCT($E$13:$E$17,F13:F17) | G18: =SUMPRODUCT($E$13:$E$17,G13:G17) | H18: =G18/F18
B20: Loss ratio (claims / premium) | C20: =H18
B21: Combined ratio (incl. brokerage) | C21: =(G18+F18*C7)/F18
B22: Breakeven ace frequency multiple | C22: =(F18*(1-C7))/G18
B23: Aces must run this much more often before cover loses money.
B24: Largest single-event exposure ($) | C24: =MAX(D13:D17)
B26: NOT BOUND: this is the submitted structure. No revised policy is bound on these terms as at August 2026.
B28: Expected claim per entry ($) — weighted | C28: =G18

Sheet Annual
B2: ANNUAL ROLL-UP (ZAR)
B3: Calendar-year totals from the monthly build. Not run-rate annualised.
C5: 2026 | D5: 2027 | E5: 2028 | F5: 2029 | G5: 2030 | H5: 2031 | I5: 2032
B6: Closing members | C6: ='Build (Monthly)'!N15 | D6: ='Build (Monthly)'!Z15 | E6: ='Build (Monthly)'!AL15 | F6: ='Build (Monthly)'!AX15 | G6: ='Build (Monthly)'!BJ15 | H6: ='Build (Monthly)'!BV15 | I6: ='Build (Monthly)'!CH15
B7: Paid entries | C7: =SUMIF('Build (Monthly)'!$C$6:$CH$6,C$5,'Build (Monthly)'!$C$20:$CH$20) | D7: =SUMIF('Build (Monthly)'!$C$6:$CH$6,D$5,'Build (Monthly)'!$C$20:$CH$20) | E7: =SUMIF('Build (Monthly)'!$C$6:$CH$6,E$5,'Build (Monthly)'!$C$20:$CH$20) | F7: =SUMIF('Build (Monthly)'!$C$6:$CH$6,F$5,'Build (Monthly)'!$C$20:$CH$20) | G7: =SUMIF('Build (Monthly)'!$C$6:$CH$6,G$5,'Build (Monthly)'!$C$20:$CH$20) | H7: =SUMIF('Build (Monthly)'!$C$6:$CH$6,H$5,'Build (Monthly)'!$C$20:$CH$20) | I7: =SUMIF('Build (Monthly)'!$C$6:$CH$6,I$5,'Build (Monthly)'!$C$20:$CH$20)
B9: REVENUE — net of third-party shares
B10: Membership | C10: =SUMIF('Build (Monthly)'!$C$6:$CH$6,C$5,'Build (Monthly)'!$C$27:$CH$27)*Assumptions!$C$6 | D10: =SUMIF('Build (Monthly)'!$C$6:$CH$6,D$5,'Build (Monthly)'!$C$27:$CH$27)*Assumptions!$C$6 | E10: =SUMIF('Build (Monthly)'!$C$6:$CH$6,E$5,'Build (Monthly)'!$C$27:$CH$27)*Assumptions!$C$6 | F10: =SUMIF('Build (Monthly)'!$C$6:$CH$6,F$5,'Build (Monthly)'!$C$27:$CH$27)*Assumptions!$C$6 | G10: =SUMIF('Build (Monthly)'!$C$6:$CH$6,G$5,'Build (Monthly)'!$C$27:$CH$27)*Assumptions!$C$6 | H10: =SUMIF('Build (Monthly)'!$C$6:$CH$6,H$5,'Build (Monthly)'!$C$27:$CH$27)*Assumptions!$C$6 | I10: =SUMIF('Build (Monthly)'!$C$6:$CH$6,I$5,'Build (Monthly)'!$C$27:$CH$27)*Assumptions!$C$6
B11: Pay-per-play | C11: =SUMIF('Build (Monthly)'!$C$6:$CH$6,C$5,'Build (Monthly)'!$C$28:$CH$28)*Assumptions!$C$6 | D11: =SUMIF('Build (Monthly)'!$C$6:$CH$6,D$5,'Build (Monthly)'!$C$28:$CH$28)*Assumptions!$C$6 | E11: =SUMIF('Build (Monthly)'!$C$6:$CH$6,E$5,'Build (Monthly)'!$C$28:$CH$28)*Assumptions!$C$6 | F11: =SUMIF('Build (Monthly)'!$C$6:$CH$6,F$5,'Build (Monthly)'!$C$28:$CH$28)*Assumptions!$C$6 | G11: =SUMIF('Build (Monthly)'!$C$6:$CH$6,G$5,'Build (Monthly)'!$C$28:$CH$28)*Assumptions!$C$6 | H11: =SUMIF('Build (Monthly)'!$C$6:$CH$6,H$5,'Build (Monthly)'!$C$28:$CH$28)*Assumptions!$C$6 | I11: =SUMIF('Build (Monthly)'!$C$6:$CH$6,I$5,'Build (Monthly)'!$C$28:$CH$28)*Assumptions!$C$6
B12: In-play upsells | C12: =SUMIF('Build (Monthly)'!$C$6:$CH$6,C$5,'Build (Monthly)'!$C$29:$CH$29)*Assumptions!$C$6 | D12: =SUMIF('Build (Monthly)'!$C$6:$CH$6,D$5,'Build (Monthly)'!$C$29:$CH$29)*Assumptions!$C$6 | E12: =SUMIF('Build (Monthly)'!$C$6:$CH$6,E$5,'Build (Monthly)'!$C$29:$CH$29)*Assumptions!$C$6 | F12: =SUMIF('Build (Monthly)'!$C$6:$CH$6,F$5,'Build (Monthly)'!$C$29:$CH$29)*Assumptions!$C$6 | G12: =SUMIF('Build (Monthly)'!$C$6:$CH$6,G$5,'Build (Monthly)'!$C$29:$CH$29)*Assumptions!$C$6 | H12: =SUMIF('Build (Monthly)'!$C$6:$CH$6,H$5,'Build (Monthly)'!$C$29:$CH$29)*Assumptions!$C$6 | I12: =SUMIF('Build (Monthly)'!$C$6:$CH$6,I$5,'Build (Monthly)'!$C$29:$CH$29)*Assumptions!$C$6
B13: Simulators | C13: 0 | D13: 2399820 | E13: 6399520 | F13: 11999100 | G13: 16000000 | H13: 22000000 | I13: 31997600
B14: Sponsorship | C14: 2500000 | D14: 3000000 | E14: 3500000 | F14: 5500000 | G14: 8500000 | H14: 10500000 | I14: 12500000
B15: TOTAL REVENUE | C15: =SUM(C10:C14) | D15: =SUM(D10:D14) | E15: =SUM(E10:E14) | F15: =SUM(F10:F14) | G15: =SUM(G10:G14) | H15: =SUM(H10:H14) | I15: =SUM(I10:I14)
B17: COST
B18: Payment processing | C18: =(SUMIF('Build (Monthly)'!$C$6:$CH$6,C$5,'Build (Monthly)'!$C$27:$CH$27)+SUMIF('Build (Monthly)'!$C$6:$CH$6,C$5,'Build (Monthly)'!$C$21:$CH$21)+SUMIF('Build (Monthly)'!$C$6:$CH$6,C$5,'Build (Monthly)'!$C$20:$CH$20)*Assumptions!$C$33*Assumptions!$C$34)*Assumptions!$C$6*Assumptions!$C$38 | D18: =(SUMIF('Build (Monthly)'!$C$6:$CH$6,D$5,'Build (Monthly)'!$C$27:$CH$27)+SUMIF('Build (Monthly)'!$C$6:$CH$6,D$5,'Build (Monthly)'!$C$21:$CH$21)+SUMIF('Build (Monthly)'!$C$6:$CH$6,D$5,'Build (Monthly)'!$C$20:$CH$20)*Assumptions!$C$33*Assumptions!$C$34)*Assumptions!$C$6*Assumptions!$C$38 | E18: =(SUMIF('Build (Monthly)'!$C$6:$CH$6,E$5,'Build (Monthly)'!$C$27:$CH$27)+SUMIF('Build (Monthly)'!$C$6:$CH$6,E$5,'Build (Monthly)'!$C$21:$CH$21)+SUMIF('Build (Monthly)'!$C$6:$CH$6,E$5,'Build (Monthly)'!$C$20:$CH$20)*Assumptions!$C$33*Assumptions!$C$34)*Assumptions!$C$6*Assumptions!$C$38 | F18: =(SUMIF('Build (Monthly)'!$C$6:$CH$6,F$5,'Build (Monthly)'!$C$27:$CH$27)+SUMIF('Build (Monthly)'!$C$6:$CH$6,F$5,'Build (Monthly)'!$C$21:$CH$21)+SUMIF('Build (Monthly)'!$C$6:$CH$6,F$5,'Build (Monthly)'!$C$20:$CH$20)*Assumptions!$C$33*Assumptions!$C$34)*Assumptions!$C$6*Assumptions!$C$38 | G18: =(SUMIF('Build (Monthly)'!$C$6:$CH$6,G$5,'Build (Monthly)'!$C$27:$CH$27)+SUMIF('Build (Monthly)'!$C$6:$CH$6,G$5,'Build (Monthly)'!$C$21:$CH$21)+SUMIF('Build (Monthly)'!$C$6:$CH$6,G$5,'Build (Monthly)'!$C$20:$CH$20)*Assumptions!$C$33*Assumptions!$C$34)*Assumptions!$C$6*Assumptions!$C$38 | H18: =(SUMIF('Build (Monthly)'!$C$6:$CH$6,H$5,'Build (Monthly)'!$C$27:$CH$27)+SUMIF('Build (Monthly)'!$C$6:$CH$6,H$5,'Build (Monthly)'!$C$21:$CH$21)+SUMIF('Build (Monthly)'!$C$6:$CH$6,H$5,'Build (Monthly)'!$C$20:$CH$20)*Assumptions!$C$33*Assumptions!$C$34)*Assumptions!$C$6*Assumptions!$C$38 | I18: =(SUMIF('Build (Monthly)'!$C$6:$CH$6,I$5,'Build (Monthly)'!$C$27:$CH$27)+SUMIF('Build (Monthly)'!$C$6:$CH$6,I$5,'Build (Monthly)'!$C$21:$CH$21)+SUMIF('Build (Monthly)'!$C$6:$CH$6,I$5,'Build (Monthly)'!$C$20:$CH$20)*Assumptions!$C$33*Assumptions!$C$34)*Assumptions!$C$6*Assumptions!$C$38
B19: Verification & claims ops | C19: =SUMIF('Build (Monthly)'!$C$6:$CH$6,C$5,'Build (Monthly)'!$C$20:$CH$20)*Assumptions!$C$39*Assumptions!$C$6 | D19: =SUMIF('Build (Monthly)'!$C$6:$CH$6,D$5,'Build (Monthly)'!$C$20:$CH$20)*Assumptions!$C$39*Assumptions!$C$6 | E19: =SUMIF('Build (Monthly)'!$C$6:$CH$6,E$5,'Build (Monthly)'!$C$20:$CH$20)*Assumptions!$C$39*Assumptions!$C$6 | F19: =SUMIF('Build (Monthly)'!$C$6:$CH$6,F$5,'Build (Monthly)'!$C$20:$CH$20)*Assumptions!$C$39*Assumptions!$C$6 | G19: =SUMIF('Build (Monthly)'!$C$6:$CH$6,G$5,'Build (Monthly)'!$C$20:$CH$20)*Assumptions!$C$39*Assumptions!$C$6 | H19: =SUMIF('Build (Monthly)'!$C$6:$CH$6,H$5,'Build (Monthly)'!$C$20:$CH$20)*Assumptions!$C$39*Assumptions!$C$6 | I19: =SUMIF('Build (Monthly)'!$C$6:$CH$6,I$5,'Build (Monthly)'!$C$20:$CH$20)*Assumptions!$C$39*Assumptions!$C$6
B20: Acquisition (CAC) | C20: =(SUMIF('Build (Monthly)'!$C$6:$CH$6,C$5,'Build (Monthly)'!$C$12:$CH$12)+SUMIF('Build (Monthly)'!$C$6:$CH$6,C$5,'Build (Monthly)'!$C$13:$CH$13))*Assumptions!$C$40*Assumptions!$C$6 | D20: =(SUMIF('Build (Monthly)'!$C$6:$CH$6,D$5,'Build (Monthly)'!$C$12:$CH$12)+SUMIF('Build (Monthly)'!$C$6:$CH$6,D$5,'Build (Monthly)'!$C$13:$CH$13))*Assumptions!$C$40*Assumptions!$C$6 | E20: =(SUMIF('Build (Monthly)'!$C$6:$CH$6,E$5,'Build (Monthly)'!$C$12:$CH$12)+SUMIF('Build (Monthly)'!$C$6:$CH$6,E$5,'Build (Monthly)'!$C$13:$CH$13))*Assumptions!$C$40*Assumptions!$C$6 | F20: =(SUMIF('Build (Monthly)'!$C$6:$CH$6,F$5,'Build (Monthly)'!$C$12:$CH$12)+SUMIF('Build (Monthly)'!$C$6:$CH$6,F$5,'Build (Monthly)'!$C$13:$CH$13))*Assumptions!$C$40*Assumptions!$C$6 | G20: =(SUMIF('Build (Monthly)'!$C$6:$CH$6,G$5,'Build (Monthly)'!$C$12:$CH$12)+SUMIF('Build (Monthly)'!$C$6:$CH$6,G$5,'Build (Monthly)'!$C$13:$CH$13))*Assumptions!$C$40*Assumptions!$C$6 | H20: =(SUMIF('Build (Monthly)'!$C$6:$CH$6,H$5,'Build (Monthly)'!$C$12:$CH$12)+SUMIF('Build (Monthly)'!$C$6:$CH$6,H$5,'Build (Monthly)'!$C$13:$CH$13))*Assumptions!$C$40*Assumptions!$C$6 | I20: =(SUMIF('Build (Monthly)'!$C$6:$CH$6,I$5,'Build (Monthly)'!$C$12:$CH$12)+SUMIF('Build (Monthly)'!$C$6:$CH$6,I$5,'Build (Monthly)'!$C$13:$CH$13))*Assumptions!$C$40*Assumptions!$C$6
B21: Brand & retention | C21: =C15*Assumptions!$C$41 | D21: =D15*Assumptions!$C$41 | E21: =E15*Assumptions!$C$41 | F21: =F15*Assumptions!$C$41 | G21: =G15*Assumptions!$C$41 | H21: =H15*Assumptions!$C$41 | I21: =I15*Assumptions!$C$41
B22: Central budget | C22: 9500000 | D22: 18000000 | E22: 28000000 | F22: 38000000 | G22: 49000000 | H22: 60000000 | I22: 72000000
B23: TOTAL COST | C23: =SUM(C18:C22) | D23: =SUM(D18:D22) | E23: =SUM(E18:E22) | F23: =SUM(F18:F22) | G23: =SUM(G18:G22) | H23: =SUM(H18:H22) | I23: =SUM(I18:I22)
B25: EBITDA | C25: =C15-C23 | D25: =D15-D23 | E25: =E15-E23 | F25: =F15-F23 | G25: =G15-G23 | H25: =H15-H23 | I25: =I15-I23
B26: EBITDA margin | C26: =C25/C15 | D26: =D25/D15 | E26: =E25/E15 | F26: =F25/F15 | G26: =G25/G15 | H26: =H25/H15 | I26: =I25/I15
B28: Capex | C28: 4000000 | D28: 3500000 | E28: 3000000 | F28: 2200000 | G28: 1800000 | H28: 1600000 | I28: 1500000
B29: Free cash flow | C29: =C25-C28 | D29: =D25-D28 | E29: =E25-E28 | F29: =F25-F28 | G29: =G25-G28 | H29: =H25-H28 | I29: =I25-I28
B30: Cumulative cash | C30: =C29 | D30: =C30+D29 | E30: =D30+E29 | F30: =E30+F29 | G30: =F30+G29 | H30: =G30+H29 | I30: =H30+I29
B32: MEMO — what the insurer sees
B33: Gross entry value | C33: =SUMIF('Build (Monthly)'!$C$6:$CH$6,C$5,'Build (Monthly)'!$C$21:$CH$21)*Assumptions!$C$6 | D33: =SUMIF('Build (Monthly)'!$C$6:$CH$6,D$5,'Build (Monthly)'!$C$21:$CH$21)*Assumptions!$C$6 | E33: =SUMIF('Build (Monthly)'!$C$6:$CH$6,E$5,'Build (Monthly)'!$C$21:$CH$21)*Assumptions!$C$6 | F33: =SUMIF('Build (Monthly)'!$C$6:$CH$6,F$5,'Build (Monthly)'!$C$21:$CH$21)*Assumptions!$C$6 | G33: =SUMIF('Build (Monthly)'!$C$6:$CH$6,G$5,'Build (Monthly)'!$C$21:$CH$21)*Assumptions!$C$6 | H33: =SUMIF('Build (Monthly)'!$C$6:$CH$6,H$5,'Build (Monthly)'!$C$21:$CH$21)*Assumptions!$C$6 | I33: =SUMIF('Build (Monthly)'!$C$6:$CH$6,I$5,'Build (Monthly)'!$C$21:$CH$21)*Assumptions!$C$6
B34: Premium ceded (24%) | C34: =SUMIF('Build (Monthly)'!$C$6:$CH$6,C$5,'Build (Monthly)'!$C$22:$CH$22)*Assumptions!$C$6 | D34: =SUMIF('Build (Monthly)'!$C$6:$CH$6,D$5,'Build (Monthly)'!$C$22:$CH$22)*Assumptions!$C$6 | E34: =SUMIF('Build (Monthly)'!$C$6:$CH$6,E$5,'Build (Monthly)'!$C$22:$CH$22)*Assumptions!$C$6 | F34: =SUMIF('Build (Monthly)'!$C$6:$CH$6,F$5,'Build (Monthly)'!$C$22:$CH$22)*Assumptions!$C$6 | G34: =SUMIF('Build (Monthly)'!$C$6:$CH$6,G$5,'Build (Monthly)'!$C$22:$CH$22)*Assumptions!$C$6 | H34: =SUMIF('Build (Monthly)'!$C$6:$CH$6,H$5,'Build (Monthly)'!$C$22:$CH$22)*Assumptions!$C$6 | I34: =SUMIF('Build (Monthly)'!$C$6:$CH$6,I$5,'Build (Monthly)'!$C$22:$CH$22)*Assumptions!$C$6
B35: Expected claims | C35: =SUMIF('Build (Monthly)'!$C$6:$CH$6,C$5,'Build (Monthly)'!$C$33:$CH$33)*Assumptions!$C$6 | D35: =SUMIF('Build (Monthly)'!$C$6:$CH$6,D$5,'Build (Monthly)'!$C$33:$CH$33)*Assumptions!$C$6 | E35: =SUMIF('Build (Monthly)'!$C$6:$CH$6,E$5,'Build (Monthly)'!$C$33:$CH$33)*Assumptions!$C$6 | F35: =SUMIF('Build (Monthly)'!$C$6:$CH$6,F$5,'Build (Monthly)'!$C$33:$CH$33)*Assumptions!$C$6 | G35: =SUMIF('Build (Monthly)'!$C$6:$CH$6,G$5,'Build (Monthly)'!$C$33:$CH$33)*Assumptions!$C$6 | H35: =SUMIF('Build (Monthly)'!$C$6:$CH$6,H$5,'Build (Monthly)'!$C$33:$CH$33)*Assumptions!$C$6 | I35: =SUMIF('Build (Monthly)'!$C$6:$CH$6,I$5,'Build (Monthly)'!$C$33:$CH$33)*Assumptions!$C$6
B36: Loss ratio | C36: =C35/C34 | D36: =D35/D34 | E36: =E35/E34 | F36: =F35/F34 | G36: =G35/G34 | H36: =H35/H34 | I36: =I35/I34

Sheet Valuation
B2: VALUATION
B3: One flat revenue multiple at every forward milestone. The entry multiple is whatever the round implies.
C5: 2026 | D5: Dec 2029 | E5: 2032
B6: Total revenue (ZAR) | C6: =Annual!C15 | D6: =Annual!F15 | E6: =Annual!I15
B7: EBITDA (ZAR) | C7: =Annual!C25 | D7: =Annual!F25 | E7: =Annual!I25
B8: Revenue multiple applied | C8: =C10/C6 | D8: =Assumptions!$C$47 | E8: =Assumptions!$C$47
B9: (2026 is the multiple the round implies, not an input)
B10: Valuation milestone (ZAR) | C10: =Assumptions!$C$9 | D10: =D6*D8 | E10: =E6*E8
B12: INVESTOR
B13: Ticket (ZAR) | C13: 8000000
B14: Stake | C14: =C13/Assumptions!$C$9
B15: Value of stake | C15: =$C$14*C10 | D15: =$C$14*D10 | E15: =$C$14*E10
B16: Multiple on ticket | C16: =C15/$C$13 | D16: =D15/$C$13 | E16: =E15/$C$13
B17: IRR to Dec 2029 (3.4 yrs from a Q3 2026 close) | D17: =D16^(1/3.4)-1
B18: Unrealised mark on a private holding, not a realised return.
B20: FUNDING
B21: Peak cumulative drawdown (ZAR) | C21: =MIN(Annual!C30:I30)
B22: Raise (ZAR) | C22: =Assumptions!$C$7
B23: Headroom | C23: =C22+C21
B25: RISKS TO THESE NUMBERS
B26: Simulator revenue depends on an operator agreement. None signed; no approach made as at Aug 2026.
B27: New-territory sponsorship partners are appointed at market entry and are not yet in place.
B28: The 2,000 opening members is a conversion target, not a current paying base.
B29: Upsell attach is modelled, not observed — the menu ships in 2027.
B30: Insurance terms are a submission, not a bound policy.
