Workbook

Sheet Read Me
B2: GET LUCKY GOLF CLUB × SANTAM
B3: Ernie Els backed Hole In One App — underwriting submission
B5: THE PROPOSITION
B6: The Ernie Els backed Hole In One App sells a golfer one shot at a hole-in-one prize on every Par 3, anywhere in the world. The golfer chooses the stake before they swing.
B7: Santam carries no acquisition cost beyond brokerage: 24% of every entry is paid over as premium, of which 20% is ceded to Indwe as brokerage, in exchange for 100% cover of every verified ace payout.
B9: THE ENTRY LADDER
B10: $1 to win $500 | $5 to win $2,500 | $10 to win $10,000 | $50 to win $50,000 | $100 to win $100,000
B11: One entry buys one swing at one Par 3. There is no subscription and no unlimited-swing exposure.
B13: WHY THE RISK IS ATTRACTIVE
B14: At amateur ace odds of 1 in 12,500 per attempt, the expected claim is 4% of entry value on the two lowest tiers and 8% on the three highest.
B15: Premium is 24% of entry value on every tier. On the modelled mix that is $4.08 of premium against $1.30 of expected claims per entry — a 31.9% loss ratio. After 20% brokerage to Indwe, the combined ratio is 51.9%.
B16: Loaded uniformly across all five tiers, aces would have to occur 2.51 times more often than amateur odds predict before the cover stops making money after brokerage — statistically negligible over 141 expected aces. The binding constraint is narrower: because Tiers 3–5 carry 95% of expected claims, loading only those tiers breaks the cover at 2.58x, or roughly 1 in 4,800 on the top three tiers. Both cases are tested on the Insurance ROI tab.
B17: Stake size is display-driven, not skill-driven. The $100 entry is bought by the player who wants an audience, not the player most likely to hole out — so the largest prizes do not attract the strongest golfers.
B19: HEADLINE NUMBERS — 36 MONTHS | C19: USD | D19: ZAR
B20: Insured swings written | C20: ='Insurance ROI'!F27 -> 1907261.6
B21: Premium income to underwriter | C21: ='Insurance ROI'!F29 -> 7781627.5 | D21: =C21*Assumptions!$C$6 -> 1.4396011e+08
B22: Broker commission to Indwe (20% of premium) | C22: ='Insurance ROI'!C7 -> 1556325.5 | D22: =C22*Assumptions!$C$6 -> 28792022
B23: Net premium retained by insurer | C23: ='Insurance ROI'!C8 -> 6225302 | D23: =C23*Assumptions!$C$6 -> 1.1516809e+08
B24: Expected claims | C24: ='Insurance ROI'!F33 -> 2479440.1 | D24: =C24*Assumptions!$C$6 -> 45869642
B25: Underwriting profit | C25: ='Insurance ROI'!F34 -> 3745861.8 | D25: =C25*Assumptions!$C$6 -> 69298444
B26: Loss ratio | C26: ='Insurance ROI'!F35 -> 0.31862745
B27: Return on premium | C27: ='Insurance ROI'!F36 -> 0.48137255
B28: Largest single-event exposure | C28: ='Insurance ROI'!C40 -> 100000 | D28: =C28*Assumptions!$C$6 -> 1850000
B30: HOW TO READ THE COLOURS
B31: BLUE text = an input you can change. These drive everything else.
B32: BLACK text = a formula. Do not type over these; they recalculate.
B33: GREEN text = a figure pulled from another tab in this workbook.
B34: GOLD fill = key risk assumption to confirm with the underwriter.
B36: THE THREE TABS
B37: 1. Assumptions — every driver, plus the five-tier prize ladder and its per-entry risk economics.
B38: 2. Build (Monthly) — 36-month player, swing and entry build, including the Ernie Partner Network ramp, with premium, expected aces and claims by month and by year.
B39: 3. Insurance ROI — the underwriting case: premium against claims, exposure profile, frequency and tier-selection stress tests, and Year 1 resilience.

Sheet Assumptions
B2: ERNIE ELS BACKED HOLE IN ONE APP — ASSUMPTIONS
B3: Blue = input you can change. Black = calculated. Yellow = key risk assumption to confirm.
B5: SCOPE & COVER
B6: ZAR per USD | C6: 18.5 | E6: FX assumption — confirm rate to use
B7: Insurance premium (% of entry revenue) | C7: 0.24 | E7: Premium ceded to underwriter
B8: Cover level (% of prize insured) | C8: 1 | E8: 100% payout cover — no retained risk
B9: Broker commission to Indwe (% of premium) | C9: 0.2 | E9: Brokerage on premium — a cost to the insurer
B11: PLAYER BASE
B12: Registered players at month 0 | C12: 2000 | E12: Current registered base
B13: Monthly player growth — Year 1 | C13: 0.105 | E13: The Ernie Els effect
B14: Monthly player growth — Year 2 | C14: 0.08 | E14: SA + first international markets
B15: Monthly player growth — Year 3 | C15: 0.07 | E15: Global markets open (UK/US/ME/Asia)
B16: Monthly churn rate | C16: 0.04 | E16: % of base lost per month
B17: ERNIE PARTNER NETWORK
B18: Players added over 3 years | C18: 200000 | E18: PGA, Golf Breaks, YGT and 100 partner courses — total incremental registered players
B19: First month players arrive | C19: 3 | E19: Integration build — no players before this month
B20: Ramp weight total (linear ramp to month 36) | C20: =(36-C19+1)*(36-C19+2)/2 -> 595 | E20: Denominator that spreads the 200,000 across the ramp
B22: ENGAGEMENT — ATTEMPTS TO ENTRIES
B23: Rounds per player per month | C23: 4 | E23: Rounds of golf played per active player
B24: Par 3 holes per round | C24: 4 | E24: Standard 18-hole course — one shot at each
B25: Par 3 attempts per player per month | C25: =C23*C24 -> 16 | E25: Maximum insurable swings available
B26: Entry conversion (% of attempts bought) | C26: 0.0625 | E26: In-app take-up on an available Par 3
B27: Paid entries per player per month | C27: =C25*C26 -> 1 | E27: Drives all revenue and all exposure
B29: ACE PROBABILITY
B30: Per-attempt hole-in-one probability | C30: 8e-05 | E30: Applied flat across all tiers
B31: Implied odds — 1 in every X attempts | C31: =1/C30 -> 12500 | E31: Sense-check on the line above
B33: PRIZE LADDER — ONE SHOT AT THE HOLE IN ONE, EVERY PAR 3
B34: Tier | C34: Entry ($) | D34: Prize ($) | E34: Mix (% of entries) | F34: Expected claim / entry ($) | G34: Premium / entry ($) | H34: Loss ratio
B35: Tier 1 | C35: 1 | D35: 500 | E35: 0.25 | F35: =D35*$C$30*$C$8 -> 0.04 | G35: =C35*$C$7 -> 0.24 | H35: =F35/G35 -> 0.16666667
B36: Tier 2 | C36: 5 | D36: 2500 | E36: 0.25 | F36: =D36*$C$30*$C$8 -> 0.2 | G36: =C36*$C$7 -> 1.2 | H36: =F36/G36 -> 0.16666667
B37: Tier 3 | C37: 10 | D37: 10000 | E37: 0.3 | F37: =D37*$C$30*$C$8 -> 0.8 | G37: =C37*$C$7 -> 2.4 | H37: =F37/G37 -> 0.33333333
B38: Tier 4 | C38: 50 | D38: 50000 | E38: 0.15 | F38: =D38*$C$30*$C$8 -> 4 | G38: =C38*$C$7 -> 12 | H38: =F38/G38 -> 0.33333333
B39: Tier 5 | C39: 100 | D39: 100000 | E39: 0.05 | F39: =D39*$C$30*$C$8 -> 8 | G39: =C39*$C$7 -> 24 | H39: =F39/G39 -> 0.33333333
B40: Weighted average / total | C40: =SUMPRODUCT($E$35:$E$39,C35:C39) -> 17 | D40: =SUMPRODUCT($E$35:$E$39,D35:D39) -> 16250 | E40: =SUM(E35:E39) -> 1 | F40: =SUMPRODUCT($E$35:$E$39,F35:F39) -> 1.3 | G40: =SUMPRODUCT($E$35:$E$39,G35:G39) -> 4.08 | H40: =F40/G40 -> 0.31862745
B41: Mix check — must total 100% | C41: =IF(ROUND(E40,6)=1,"OK","ERROR: mix does not total 100%") -> OK

Sheet Build (Monthly)
B2: ERNIE ELS BACKED HOLE IN ONE APP — 36-MONTH BUILD
B3: One paid shot at the hole-in-one prize on every Par 3. All drivers live on the Assumptions tab. | AN3: ANNUAL SUMMARY
B5: Month | C5: 1 | D5: =C5+1 -> 2 | E5: =D5+1 -> 3 | F5: =E5+1 -> 4 | G5: =F5+1 -> 5 | H5: =G5+1 -> 6 | I5: =H5+1 -> 7 | J5: =I5+1 -> 8 | K5: =J5+1 -> 9 | ... AL5: =AK5+1 -> 36 | AN5: Year 1 | AO5: Year 2 | AP5: Year 3
B6: Year | C6: =ROUNDUP(C5/12,0) -> 1 | D6: =ROUNDUP(D5/12,0) -> 1 | E6: =ROUNDUP(E5/12,0) -> 1 | F6: =ROUNDUP(F5/12,0) -> 1 | G6: =ROUNDUP(G5/12,0) -> 1 | H6: =ROUNDUP(H5/12,0) -> 1 | I6: =ROUNDUP(I5/12,0) -> 1 | J6: =ROUNDUP(J5/12,0) -> 1 | ... AL6: =ROUNDUP(AL5/12,0) -> 3 | AN6: 1 | AO6: 2 | AP6: 3
B7: Monthly growth rate applied | C7: =CHOOSE(C$6,Assumptions!$C$13,Assumptions!$C$14,Assumptions!$C$15) -> 0.105 | D7: =CHOOSE(D$6,Assumptions!$C$13,Assumptions!$C$14,Assumptions!$C$15) -> 0.105 | E7: =CHOOSE(E$6,Assumptions!$C$13,Assumptions!$C$14,Assumptions!$C$15) -> 0.105 | F7: =CHOOSE(F$6,Assumptions!$C$13,Assumptions!$C$14,Assumptions!$C$15) -> 0.105 | G7: =CHOOSE(G$6,Assumptions!$C$13,Assumptions!$C$14,Assumptions!$C$15) -> 0.105 | H7: =CHOOSE(H$6,Assumptions!$C$13,Assumptions!$C$14,Assumptions!$C$15) -> 0.105 | I7: =CHOOSE(I$6,Assumptions!$C$13,Assumptions!$C$14,Assumptions!$C$15) -> 0.105 | J7: =CHOOSE(J$6,Assumptions!$C$13,Assumptions!$C$14,Assumptions!$C$15) -> 0.105 | ... AL7: =CHOOSE(AL$6,Assumptions!$C$13,Assumptions!$C$14,Assumptions!$C$15) -> 0.07
B9: PLAYERS
B10: Opening registered players | C10: =C11+C12 -> 2000 | D10: =D11+D12 -> 2130 | E10: =E11+E12 -> 2268.45 | F10: =F11+F12 -> 2752.0337 | G10: =G11+G12 -> 3567.8907 | H10: =H11+H12 -> 4703.7364 | I10: =I11+I12 -> 6147.8429 | J10: =J11+J12 -> 7889.0213 | ... AL10: =AL11+AL12 -> 137501.51 | AN10: {=INDEX($C$10:$AL$10,(AN$6-1)*12+1)} -> 2000 | AO10: {=INDEX($C$10:$AL$10,(AO$6-1)*12+1)} -> 20695.027 | AP10: {=INDEX($C$10:$AL$10,(AP$6-1)*12+1)} -> 72165.29
B11: of which — organic cohort | C11: =Assumptions!$C$12 -> 2000 | D11: =C11+C13-C11*Assumptions!$C$16 -> 2130 | E11: =D11+D13-D11*Assumptions!$C$16 -> 2268.45 | F11: =E11+E13-E11*Assumptions!$C$16 -> 2415.8993 | G11: =F11+F13-F11*Assumptions!$C$16 -> 2572.9327 | H11: =G11+G13-G11*Assumptions!$C$16 -> 2740.1733 | I11: =H11+H13-H11*Assumptions!$C$16 -> 2918.2846 | J11: =I11+I13-I11*Assumptions!$C$16 -> 3107.9731 | K11: =J11+J13-J11*Assumptions!$C$16 -> 3309.9913 | ... AL11: =AK11+AK13-AK11*Assumptions!$C$16 -> 9437.0191 | AN11: {=INDEX($C$11:$AL$11,(AN$6-1)*12+1)} -> 2000 | AO11: {=INDEX($C$11:$AL$11,(AO$6-1)*12+1)} -> 4258.1925 | AP11: {=INDEX($C$11:$AL$11,(AP$6-1)*12+1)} -> 6817.5034
B12: of which — Ernie Partner Network cohort | C12: 0 | D12: =C12+C14-C12*Assumptions!$C$16 -> 0 | E12: =D12+D14-D12*Assumptions!$C$16 -> 0 | F12: =E12+E14-E12*Assumptions!$C$16 -> 336.13445 | G12: =F12+F14-F12*Assumptions!$C$16 -> 994.95798 | H12: =G12+G14-G12*Assumptions!$C$16 -> 1963.563 | I12: =H12+H14-H12*Assumptions!$C$16 -> 3229.5583 | J12: =I12+I14-I12*Assumptions!$C$16 -> 4781.0483 | K12: =J12+J14-J12*Assumptions!$C$16 -> 6606.613 | ... AL12: =AK12+AK14-AK12*Assumptions!$C$16 -> 128064.49 | AN12: {=INDEX($C$12:$AL$12,(AN$6-1)*12+1)} -> 0 | AO12: {=INDEX($C$12:$AL$12,(AO$6-1)*12+1)} -> 16436.834 | AP12: {=INDEX($C$12:$AL$12,(AP$6-1)*12+1)} -> 65347.787
B13: New players — organic growth | C13: =C11*C$7 -> 210 | D13: =D11*D$7 -> 223.65 | E13: =E11*E$7 -> 238.18725 | F13: =F11*F$7 -> 253.66942 | G13: =G11*G$7 -> 270.15793 | H13: =H11*H$7 -> 287.7182 | I13: =I11*I$7 -> 306.41988 | J13: =J11*J$7 -> 326.33717 | ... AL13: =AL11*AL$7 -> 660.59133 | AN13: =SUMIF($C$6:$AL$6,AN$6,$C13:$AL13) -> 3647.8494 | AO13: =SUMIF($C$6:$AL$6,AO$6,$C13:$AL13) -> 5118.6218 | AP13: =SUMIF($C$6:$AL$6,AP$6,$C13:$AL13) -> 6772.7946
B14: New players — Ernie Partner Network | C14: =IF(C$5<Assumptions!$C$19,0,Assumptions!$C$18*(C$5-Assumptions!$C$19+1)/Assumptions!$C$20) -> 0 | D14: =IF(D$5<Assumptions!$C$19,0,Assumptions!$C$18*(D$5-Assumptions!$C$19+1)/Assumptions!$C$20) -> 0 | E14: =IF(E$5<Assumptions!$C$19,0,Assumptions!$C$18*(E$5-Assumptions!$C$19+1)/Assumptions!$C$20) -> 336.13445 | F14: =IF(F$5<Assumptions!$C$19,0,Assumptions!$C$18*(F$5-Assumptions!$C$19+1)/Assumptions!$C$20) -> 672.26891 | G14: =IF(G$5<Assumptions!$C$19,0,Assumptions!$C$18*(G$5-Assumptions!$C$19+1)/Assumptions!$C$20) -> 1008.4034 | H14: =IF(H$5<Assumptions!$C$19,0,Assumptions!$C$18*(H$5-Assumptions!$C$19+1)/Assumptions!$C$20) -> 1344.5378 | I14: =IF(I$5<Assumptions!$C$19,0,Assumptions!$C$18*(I$5-Assumptions!$C$19+1)/Assumptions!$C$20) -> 1680.6723 | J14: =IF(J$5<Assumptions!$C$19,0,Assumptions!$C$18*(J$5-Assumptions!$C$19+1)/Assumptions!$C$20) -> 2016.8067 | ... AL14: =IF(AL$5<Assumptions!$C$19,0,Assumptions!$C$18*(AL$5-Assumptions!$C$19+1)/Assumptions!$C$20) -> 11428.571 | AN14: =SUMIF($C$6:$AL$6,AN$6,$C14:$AL14) -> 18487.395 | AO14: =SUMIF($C$6:$AL$6,AO$6,$C14:$AL14) -> 66554.622 | AP14: =SUMIF($C$6:$AL$6,AP$6,$C14:$AL14) -> 114957.98
B15: Players churned | C15: =-C10*Assumptions!$C$16 -> -80 | D15: =-D10*Assumptions!$C$16 -> -85.2 | E15: =-E10*Assumptions!$C$16 -> -90.738 | F15: =-F10*Assumptions!$C$16 -> -110.08135 | G15: =-G10*Assumptions!$C$16 -> -142.71563 | H15: =-H10*Assumptions!$C$16 -> -188.14945 | I15: =-I10*Assumptions!$C$16 -> -245.91372 | J15: =-J10*Assumptions!$C$16 -> -315.56085 | ... AL15: =-AL10*Assumptions!$C$16 -> -5500.0604 | AN15: =SUMIF($C$6:$AL$6,AN$6,$C15:$AL15) -> -3440.2177 | AO15: =SUMIF($C$6:$AL$6,AO$6,$C15:$AL15) -> -20202.98 | AP15: =SUMIF($C$6:$AL$6,AP$6,$C15:$AL15) -> -49805.455
B16: Closing registered players | C16: =C10+C13+C14+C15 -> 2130 | D16: =D10+D13+D14+D15 -> 2268.45 | E16: =E10+E13+E14+E15 -> 2752.0337 | F16: =F10+F13+F14+F15 -> 3567.8907 | G16: =G10+G13+G14+G15 -> 4703.7364 | H16: =H10+H13+H14+H15 -> 6147.8429 | I16: =I10+I13+I14+I15 -> 7889.0213 | J16: =J10+J13+J14+J15 -> 9916.6044 | ... AL16: =AL10+AL13+AL14+AL15 -> 144090.61 | AN16: {=INDEX($C$16:$AL$16,AN$6*12)} -> 20695.027 | AO16: {=INDEX($C$16:$AL$16,AO$6*12)} -> 72165.29 | AP16: {=INDEX($C$16:$AL$16,AP$6*12)} -> 144090.61
B17: Average active players | C17: =AVERAGE(C10,C16) -> 2065 | D17: =AVERAGE(D10,D16) -> 2199.225 | E17: =AVERAGE(E10,E16) -> 2510.2419 | F17: =AVERAGE(F10,F16) -> 3159.9622 | G17: =AVERAGE(G10,G16) -> 4135.8135 | H17: =AVERAGE(H10,H16) -> 5425.7896 | I17: =AVERAGE(I10,I16) -> 7018.4321 | J17: =AVERAGE(J10,J16) -> 8902.8129 | ... AL17: =AVERAGE(AL10,AL16) -> 140796.06 | AN17: =SUMIF($C$6:$AL$6,AN$6,$C17:$AL17)/12 -> 7946.0797 | AO17: =SUMIF($C$6:$AL$6,AO$6,$C17:$AL17)/12 -> 44234.136 | AP17: =SUMIF($C$6:$AL$6,AP$6,$C17:$AL17)/12 -> 106758.25
B19: VOLUME — SWINGS & ENTRIES
B20: Par 3 attempts available | C20: =C17*Assumptions!$C$25 -> 33040 | D20: =D17*Assumptions!$C$25 -> 35187.6 | E20: =E17*Assumptions!$C$25 -> 40163.87 | F20: =F17*Assumptions!$C$25 -> 50559.395 | G20: =G17*Assumptions!$C$25 -> 66173.016 | H20: =H17*Assumptions!$C$25 -> 86812.634 | I20: =I17*Assumptions!$C$25 -> 112294.91 | J20: =J17*Assumptions!$C$25 -> 142445.01 | ... AL20: =AL17*Assumptions!$C$25 -> 2252737 | AN20: =SUMIF($C$6:$AL$6,AN$6,$C20:$AL20) -> 1525647.3 | AO20: =SUMIF($C$6:$AL$6,AO$6,$C20:$AL20) -> 8492954.1 | AP20: =SUMIF($C$6:$AL$6,AP$6,$C20:$AL20) -> 20497585
B21: Paid entries (total) | C21: =C20*Assumptions!$C$26 -> 2065 | D21: =D20*Assumptions!$C$26 -> 2199.225 | E21: =E20*Assumptions!$C$26 -> 2510.2419 | F21: =F20*Assumptions!$C$26 -> 3159.9622 | G21: =G20*Assumptions!$C$26 -> 4135.8135 | H21: =H20*Assumptions!$C$26 -> 5425.7896 | I21: =I20*Assumptions!$C$26 -> 7018.4321 | J21: =J20*Assumptions!$C$26 -> 8902.8129 | ... AL21: =AL20*Assumptions!$C$26 -> 140796.06 | AN21: =SUMIF($C$6:$AL$6,AN$6,$C21:$AL21) -> 95352.956 | AO21: =SUMIF($C$6:$AL$6,AO$6,$C21:$AL21) -> 530809.63 | AP21: =SUMIF($C$6:$AL$6,AP$6,$C21:$AL21) -> 1281099
B22: Tier 1 entries ($1 → $500) | C22: =C$21*Assumptions!$E$35 -> 516.25 | D22: =D$21*Assumptions!$E$35 -> 549.80625 | E22: =E$21*Assumptions!$E$35 -> 627.56046 | F22: =F$21*Assumptions!$E$35 -> 789.99055 | G22: =G$21*Assumptions!$E$35 -> 1033.9534 | H22: =H$21*Assumptions!$E$35 -> 1356.4474 | I22: =I$21*Assumptions!$E$35 -> 1754.608 | J22: =J$21*Assumptions!$E$35 -> 2225.7032 | ... AL22: =AL$21*Assumptions!$E$35 -> 35199.015 | AN22: =SUMIF($C$6:$AL$6,AN$6,$C22:$AL22) -> 23838.239 | AO22: =SUMIF($C$6:$AL$6,AO$6,$C22:$AL22) -> 132702.41 | AP22: =SUMIF($C$6:$AL$6,AP$6,$C22:$AL22) -> 320274.76
B23: Tier 2 entries ($5 → $2,500) | C23: =C$21*Assumptions!$E$36 -> 516.25 | D23: =D$21*Assumptions!$E$36 -> 549.80625 | E23: =E$21*Assumptions!$E$36 -> 627.56046 | F23: =F$21*Assumptions!$E$36 -> 789.99055 | G23: =G$21*Assumptions!$E$36 -> 1033.9534 | H23: =H$21*Assumptions!$E$36 -> 1356.4474 | I23: =I$21*Assumptions!$E$36 -> 1754.608 | J23: =J$21*Assumptions!$E$36 -> 2225.7032 | ... AL23: =AL$21*Assumptions!$E$36 -> 35199.015 | AN23: =SUMIF($C$6:$AL$6,AN$6,$C23:$AL23) -> 23838.239 | AO23: =SUMIF($C$6:$AL$6,AO$6,$C23:$AL23) -> 132702.41 | AP23: =SUMIF($C$6:$AL$6,AP$6,$C23:$AL23) -> 320274.76
B24: Tier 3 entries ($10 → $10,000) | C24: =C$21*Assumptions!$E$37 -> 619.5 | D24: =D$21*Assumptions!$E$37 -> 659.7675 | E24: =E$21*Assumptions!$E$37 -> 753.07256 | F24: =F$21*Assumptions!$E$37 -> 947.98866 | G24: =G$21*Assumptions!$E$37 -> 1240.7441 | H24: =H$21*Assumptions!$E$37 -> 1627.7369 | I24: =I$21*Assumptions!$E$37 -> 2105.5296 | J24: =J$21*Assumptions!$E$37 -> 2670.8439 | ... AL24: =AL$21*Assumptions!$E$37 -> 42238.818 | AN24: =SUMIF($C$6:$AL$6,AN$6,$C24:$AL24) -> 28605.887 | AO24: =SUMIF($C$6:$AL$6,AO$6,$C24:$AL24) -> 159242.89 | AP24: =SUMIF($C$6:$AL$6,AP$6,$C24:$AL24) -> 384329.71
B25: Tier 4 entries ($50 → $50,000) | C25: =C$21*Assumptions!$E$38 -> 309.75 | D25: =D$21*Assumptions!$E$38 -> 329.88375 | E25: =E$21*Assumptions!$E$38 -> 376.53628 | F25: =F$21*Assumptions!$E$38 -> 473.99433 | G25: =G$21*Assumptions!$E$38 -> 620.37203 | H25: =H$21*Assumptions!$E$38 -> 813.86844 | I25: =I$21*Assumptions!$E$38 -> 1052.7648 | J25: =J$21*Assumptions!$E$38 -> 1335.4219 | ... AL25: =AL$21*Assumptions!$E$38 -> 21119.409 | AN25: =SUMIF($C$6:$AL$6,AN$6,$C25:$AL25) -> 14302.943 | AO25: =SUMIF($C$6:$AL$6,AO$6,$C25:$AL25) -> 79621.445 | AP25: =SUMIF($C$6:$AL$6,AP$6,$C25:$AL25) -> 192164.86
B26: Tier 5 entries ($100 → $100,000) | C26: =C$21*Assumptions!$E$39 -> 103.25 | D26: =D$21*Assumptions!$E$39 -> 109.96125 | E26: =E$21*Assumptions!$E$39 -> 125.51209 | F26: =F$21*Assumptions!$E$39 -> 157.99811 | G26: =G$21*Assumptions!$E$39 -> 206.79068 | H26: =H$21*Assumptions!$E$39 -> 271.28948 | I26: =I$21*Assumptions!$E$39 -> 350.92161 | J26: =J$21*Assumptions!$E$39 -> 445.14064 | ... AL26: =AL$21*Assumptions!$E$39 -> 7039.8031 | AN26: =SUMIF($C$6:$AL$6,AN$6,$C26:$AL26) -> 4767.6478 | AO26: =SUMIF($C$6:$AL$6,AO$6,$C26:$AL26) -> 26540.482 | AP26: =SUMIF($C$6:$AL$6,AP$6,$C26:$AL26) -> 64054.952
B28: ENTRY REVENUE ($)
B29: Tier 1 revenue | C29: =C22*Assumptions!$C$35 -> 516.25 | D29: =D22*Assumptions!$C$35 -> 549.80625 | E29: =E22*Assumptions!$C$35 -> 627.56046 | F29: =F22*Assumptions!$C$35 -> 789.99055 | G29: =G22*Assumptions!$C$35 -> 1033.9534 | H29: =H22*Assumptions!$C$35 -> 1356.4474 | I29: =I22*Assumptions!$C$35 -> 1754.608 | J29: =J22*Assumptions!$C$35 -> 2225.7032 | ... AL29: =AL22*Assumptions!$C$35 -> 35199.015 | AN29: =SUMIF($C$6:$AL$6,AN$6,$C29:$AL29) -> 23838.239 | AO29: =SUMIF($C$6:$AL$6,AO$6,$C29:$AL29) -> 132702.41 | AP29: =SUMIF($C$6:$AL$6,AP$6,$C29:$AL29) -> 320274.76
B30: Tier 2 revenue | C30: =C23*Assumptions!$C$36 -> 2581.25 | D30: =D23*Assumptions!$C$36 -> 2749.0313 | E30: =E23*Assumptions!$C$36 -> 3137.8023 | F30: =F23*Assumptions!$C$36 -> 3949.9527 | G30: =G23*Assumptions!$C$36 -> 5169.7669 | H30: =H23*Assumptions!$C$36 -> 6782.237 | I30: =I23*Assumptions!$C$36 -> 8773.0402 | J30: =J23*Assumptions!$C$36 -> 11128.516 | ... AL30: =AL23*Assumptions!$C$36 -> 175995.08 | AN30: =SUMIF($C$6:$AL$6,AN$6,$C30:$AL30) -> 119191.2 | AO30: =SUMIF($C$6:$AL$6,AO$6,$C30:$AL30) -> 663512.04 | AP30: =SUMIF($C$6:$AL$6,AP$6,$C30:$AL30) -> 1601373.8
B31: Tier 3 revenue | C31: =C24*Assumptions!$C$37 -> 6195 | D31: =D24*Assumptions!$C$37 -> 6597.675 | E31: =E24*Assumptions!$C$37 -> 7530.7256 | F31: =F24*Assumptions!$C$37 -> 9479.8866 | G31: =G24*Assumptions!$C$37 -> 12407.441 | H31: =H24*Assumptions!$C$37 -> 16277.369 | I31: =I24*Assumptions!$C$37 -> 21055.296 | J31: =J24*Assumptions!$C$37 -> 26708.439 | ... AL31: =AL24*Assumptions!$C$37 -> 422388.18 | AN31: =SUMIF($C$6:$AL$6,AN$6,$C31:$AL31) -> 286058.87 | AO31: =SUMIF($C$6:$AL$6,AO$6,$C31:$AL31) -> 1592428.9 | AP31: =SUMIF($C$6:$AL$6,AP$6,$C31:$AL31) -> 3843297.1
B32: Tier 4 revenue | C32: =C25*Assumptions!$C$38 -> 15487.5 | D32: =D25*Assumptions!$C$38 -> 16494.188 | E32: =E25*Assumptions!$C$38 -> 18826.814 | F32: =F25*Assumptions!$C$38 -> 23699.716 | G32: =G25*Assumptions!$C$38 -> 31018.601 | H32: =H25*Assumptions!$C$38 -> 40693.422 | I32: =I25*Assumptions!$C$38 -> 52638.241 | J32: =J25*Assumptions!$C$38 -> 66771.097 | ... AL32: =AL25*Assumptions!$C$38 -> 1055970.5 | AN32: =SUMIF($C$6:$AL$6,AN$6,$C32:$AL32) -> 715147.17 | AO32: =SUMIF($C$6:$AL$6,AO$6,$C32:$AL32) -> 3981072.2 | AP32: =SUMIF($C$6:$AL$6,AP$6,$C32:$AL32) -> 9608242.8
B33: Tier 5 revenue | C33: =C26*Assumptions!$C$39 -> 10325 | D33: =D26*Assumptions!$C$39 -> 10996.125 | E33: =E26*Assumptions!$C$39 -> 12551.209 | F33: =F26*Assumptions!$C$39 -> 15799.811 | G33: =G26*Assumptions!$C$39 -> 20679.068 | H33: =H26*Assumptions!$C$39 -> 27128.948 | I33: =I26*Assumptions!$C$39 -> 35092.161 | J33: =J26*Assumptions!$C$39 -> 44514.064 | ... AL33: =AL26*Assumptions!$C$39 -> 703980.31 | AN33: =SUMIF($C$6:$AL$6,AN$6,$C33:$AL33) -> 476764.78 | AO33: =SUMIF($C$6:$AL$6,AO$6,$C33:$AL33) -> 2654048.2 | AP33: =SUMIF($C$6:$AL$6,AP$6,$C33:$AL33) -> 6405495.2
B34: Total entry revenue | C34: =SUM(C29:C33) -> 35105 | D34: =SUM(D29:D33) -> 37386.825 | E34: =SUM(E29:E33) -> 42674.111 | F34: =SUM(F29:F33) -> 53719.357 | G34: =SUM(G29:G33) -> 70308.83 | H34: =SUM(H29:H33) -> 92238.424 | I34: =SUM(I29:I33) -> 119313.35 | J34: =SUM(J29:J33) -> 151347.82 | ... AL34: =SUM(AL29:AL33) -> 2393533 | AN34: =SUMIF($C$6:$AL$6,AN$6,$C34:$AL34) -> 1621000.3 | AO34: =SUMIF($C$6:$AL$6,AO$6,$C34:$AL34) -> 9023763.8 | AP34: =SUMIF($C$6:$AL$6,AP$6,$C34:$AL34) -> 21778684
B36: PREMIUM & INSURED EXPOSURE ($)
B37: Premium income to underwriter (24% of entries) | C37: =C34*Assumptions!$C$7 -> 8425.2 | D37: =D34*Assumptions!$C$7 -> 8972.838 | E37: =E34*Assumptions!$C$7 -> 10241.787 | F37: =F34*Assumptions!$C$7 -> 12892.646 | G37: =G34*Assumptions!$C$7 -> 16874.119 | H37: =H34*Assumptions!$C$7 -> 22137.222 | I37: =I34*Assumptions!$C$7 -> 28635.203 | J37: =J34*Assumptions!$C$7 -> 36323.477 | ... AL37: =AL34*Assumptions!$C$7 -> 574447.93 | AN37: =SUMIF($C$6:$AL$6,AN$6,$C37:$AL37) -> 389040.06 | AO37: =SUMIF($C$6:$AL$6,AO$6,$C37:$AL37) -> 2165703.3 | AP37: =SUMIF($C$6:$AL$6,AP$6,$C37:$AL37) -> 5226884.1
B38: Broker commission to Indwe (20% of premium) | C38: =C37*Assumptions!$C$9 -> 1685.04 | D38: =D37*Assumptions!$C$9 -> 1794.5676 | E38: =E37*Assumptions!$C$9 -> 2048.3574 | F38: =F37*Assumptions!$C$9 -> 2578.5292 | G38: =G37*Assumptions!$C$9 -> 3374.8238 | H38: =H37*Assumptions!$C$9 -> 4427.4443 | I38: =I37*Assumptions!$C$9 -> 5727.0406 | J38: =J37*Assumptions!$C$9 -> 7264.6953 | ... AL38: =AL37*Assumptions!$C$9 -> 114889.59 | AN38: =SUMIF($C$6:$AL$6,AN$6,$C38:$AL38) -> 77808.012 | AO38: =SUMIF($C$6:$AL$6,AO$6,$C38:$AL38) -> 433140.66 | AP38: =SUMIF($C$6:$AL$6,AP$6,$C38:$AL38) -> 1045376.8
B39: Expected aces (count) | C39: =C21*Assumptions!$C$30 -> 0.1652 | D39: =D21*Assumptions!$C$30 -> 0.175938 | E39: =E21*Assumptions!$C$30 -> 0.20081935 | F39: =F21*Assumptions!$C$30 -> 0.25279698 | G39: =G21*Assumptions!$C$30 -> 0.33086508 | H39: =H21*Assumptions!$C$30 -> 0.43406317 | I39: =I21*Assumptions!$C$30 -> 0.56147457 | J39: =J21*Assumptions!$C$30 -> 0.71222503 | ... AL39: =AL21*Assumptions!$C$30 -> 11.263685 | AN39: =SUMIF($C$6:$AL$6,AN$6,$C39:$AL39) -> 7.6282365 | AO39: =SUMIF($C$6:$AL$6,AO$6,$C39:$AL39) -> 42.464771 | AP39: =SUMIF($C$6:$AL$6,AP$6,$C39:$AL39) -> 102.48792
B40: Expected claims payable | C40: =SUMPRODUCT(C22:C26,Assumptions!$D$35:$D$39)*Assumptions!$C$30*Assumptions!$C$8 -> 2684.5 | D40: =SUMPRODUCT(D22:D26,Assumptions!$D$35:$D$39)*Assumptions!$C$30*Assumptions!$C$8 -> 2858.9925 | E40: =SUMPRODUCT(E22:E26,Assumptions!$D$35:$D$39)*Assumptions!$C$30*Assumptions!$C$8 -> 3263.3144 | F40: =SUMPRODUCT(F22:F26,Assumptions!$D$35:$D$39)*Assumptions!$C$30*Assumptions!$C$8 -> 4107.9509 | G40: =SUMPRODUCT(G22:G26,Assumptions!$D$35:$D$39)*Assumptions!$C$30*Assumptions!$C$8 -> 5376.5576 | H40: =SUMPRODUCT(H22:H26,Assumptions!$D$35:$D$39)*Assumptions!$C$30*Assumptions!$C$8 -> 7053.5265 | I40: =SUMPRODUCT(I22:I26,Assumptions!$D$35:$D$39)*Assumptions!$C$30*Assumptions!$C$8 -> 9123.9618 | J40: =SUMPRODUCT(J22:J26,Assumptions!$D$35:$D$39)*Assumptions!$C$30*Assumptions!$C$8 -> 11573.657 | ... AL40: =SUMPRODUCT(AL22:AL26,Assumptions!$D$35:$D$39)*Assumptions!$C$30*Assumptions!$C$8 -> 183034.88 | AN40: =SUMIF($C$6:$AL$6,AN$6,$C40:$AL40) -> 123958.84 | AO40: =SUMIF($C$6:$AL$6,AO$6,$C40:$AL40) -> 690052.52 | AP40: =SUMIF($C$6:$AL$6,AP$6,$C40:$AL40) -> 1665428.8
B41: Expected underwriting profit (after brokerage) | C41: =C37-C38-C40 -> 4055.66 | D41: =D37-D38-D40 -> 4319.2779 | E41: =E37-E38-E40 -> 4930.115 | F41: =F37-F38-F40 -> 6206.1657 | G41: =G37-G38-G40 -> 8122.7377 | H41: =H37-H38-H40 -> 10656.251 | I41: =I37-I38-I40 -> 13784.201 | J41: =J37-J38-J40 -> 17485.124 | ... AL41: =AL37-AL38-AL40 -> 276523.46 | AN41: =AN37-AN38-AN40 -> 187273.21 | AO41: =AO37-AO38-AO40 -> 1042510.1 | AP41: =AP37-AP38-AP40 -> 2516078.5
B42: Largest single-event exposure | C42: =MAX(Assumptions!$D$35:$D$39) -> 100000 | D42: =MAX(Assumptions!$D$35:$D$39) -> 100000 | E42: =MAX(Assumptions!$D$35:$D$39) -> 100000 | F42: =MAX(Assumptions!$D$35:$D$39) -> 100000 | G42: =MAX(Assumptions!$D$35:$D$39) -> 100000 | H42: =MAX(Assumptions!$D$35:$D$39) -> 100000 | I42: =MAX(Assumptions!$D$35:$D$39) -> 100000 | J42: =MAX(Assumptions!$D$35:$D$39) -> 100000 | ... AL42: =MAX(Assumptions!$D$35:$D$39) -> 100000 | AN42: =MAX($C$42:$AL$42) -> 100000 | AO42: =MAX($C$42:$AL$42) -> 100000 | AP42: =MAX($C$42:$AL$42) -> 100000

Sheet Insurance ROI
B2: UNDERWRITER RETURN ON RISK — SANTAM SUBMISSION
B3: 24% of every entry is ceded as premium, in exchange for 100% cover of every verified hole-in-one payout.
B5: HEADLINE — 36 MONTHS
B6: Premium income ceded to underwriter | C6: =SUM('Build (Monthly)'!AN37:AP37) -> 7781627.5 | D6: =C6*Assumptions!$C$6 -> 1.4396011e+08 | E6: ← ZAR equivalent at the FX rate on the Assumptions tab
B7: Broker commission to Indwe (20% of premium) | C7: =C6*Assumptions!$C$9 -> 1556325.5 | D7: =C7*Assumptions!$C$6 -> 28792022
B8: Net premium retained by insurer | C8: =C6-C7 -> 6225302 | D8: =C8*Assumptions!$C$6 -> 1.1516809e+08
B9: Expected claims paid | C9: =SUM('Build (Monthly)'!AN40:AP40) -> 2479440.1 | D9: =C9*Assumptions!$C$6 -> 45869642
B10: Underwriting profit | C10: =C8-C9 -> 3745861.8 | D10: =C10*Assumptions!$C$6 -> 69298444
B11: Loss ratio (claims ÷ premium) | C11: =C9/C6 -> 0.31862745
B12: Combined ratio (claims + brokerage ÷ premium) | C12: =(C9+C7)/C6 -> 0.51862745
B13: Return on premium | C13: =C10/C6 -> 0.48137255
B14: Breakeven ace frequency multiple | C14: =C8/C9 -> 2.5107692 | E14: Aces must occur this many times more often than amateur odds predict before cover runs at a loss
B16: PER-ENTRY ECONOMICS BY TIER
B17: Tier | C17: Entry ($) | D17: Prize ($) | E17: Mix of entries | F17: Premium / entry | G17: Expected claim / entry | H17: Loss ratio
B18: =Assumptions!B35 -> Tier 1 | C18: =Assumptions!C35 -> 1 | D18: =Assumptions!D35 -> 500 | E18: =Assumptions!E35 -> 0.25 | F18: =Assumptions!G35 -> 0.24 | G18: =Assumptions!F35 -> 0.04 | H18: =G18/F18 -> 0.16666667
B19: =Assumptions!B36 -> Tier 2 | C19: =Assumptions!C36 -> 5 | D19: =Assumptions!D36 -> 2500 | E19: =Assumptions!E36 -> 0.25 | F19: =Assumptions!G36 -> 1.2 | G19: =Assumptions!F36 -> 0.2 | H19: =G19/F19 -> 0.16666667
B20: =Assumptions!B37 -> Tier 3 | C20: =Assumptions!C37 -> 10 | D20: =Assumptions!D37 -> 10000 | E20: =Assumptions!E37 -> 0.3 | F20: =Assumptions!G37 -> 2.4 | G20: =Assumptions!F37 -> 0.8 | H20: =G20/F20 -> 0.33333333
B21: =Assumptions!B38 -> Tier 4 | C21: =Assumptions!C38 -> 50 | D21: =Assumptions!D38 -> 50000 | E21: =Assumptions!E38 -> 0.15 | F21: =Assumptions!G38 -> 12 | G21: =Assumptions!F38 -> 4 | H21: =G21/F21 -> 0.33333333
B22: =Assumptions!B39 -> Tier 5 | C22: =Assumptions!C39 -> 100 | D22: =Assumptions!D39 -> 100000 | E22: =Assumptions!E39 -> 0.05 | F22: =Assumptions!G39 -> 24 | G22: =Assumptions!F39 -> 8 | H22: =G22/F22 -> 0.33333333
B23: Weighted average | C23: =Assumptions!C40 -> 17 | D23: =Assumptions!D40 -> 16250 | E23: =Assumptions!E40 -> 1 | F23: =Assumptions!G40 -> 4.08 | G23: =Assumptions!F40 -> 1.3 | H23: =G23/F23 -> 0.31862745
B25: ANNUAL PREMIUM vs CLAIMS
C26: Year 1 | D26: Year 2 | E26: Year 3 | F26: 3-Year Total | G26: 3-Year Total (ZAR)
B27: Paid entries (insured swings) | C27: ='Build (Monthly)'!AN21 -> 95352.956 | D27: ='Build (Monthly)'!AO21 -> 530809.63 | E27: ='Build (Monthly)'!AP21 -> 1281099 | F27: =SUM(C27:E27) -> 1907261.6
B28: Entry revenue | C28: ='Build (Monthly)'!AN34 -> 1621000.3 | D28: ='Build (Monthly)'!AO34 -> 9023763.8 | E28: ='Build (Monthly)'!AP34 -> 21778684 | F28: =SUM(C28:E28) -> 32423448 | G28: =F28*Assumptions!$C$6 -> 5.9983378e+08
B29: Premium income (24% of entry revenue) | C29: ='Build (Monthly)'!AN37 -> 389040.06 | D29: ='Build (Monthly)'!AO37 -> 2165703.3 | E29: ='Build (Monthly)'!AP37 -> 5226884.1 | F29: =SUM(C29:E29) -> 7781627.5 | G29: =F29*Assumptions!$C$6 -> 1.4396011e+08
B30: Broker commission to Indwe (20% of premium) | C30: =C29*Assumptions!$C$9 -> 77808.012 | D30: =D29*Assumptions!$C$9 -> 433140.66 | E30: =E29*Assumptions!$C$9 -> 1045376.8 | F30: =SUM(C30:E30) -> 1556325.5 | G30: =F30*Assumptions!$C$6 -> 28792022
B31: Net premium retained by insurer | C31: =C29-C30 -> 311232.05 | D31: =D29-D30 -> 1732562.6 | E31: =E29-E30 -> 4181507.3 | F31: =SUM(C31:E31) -> 6225302 | G31: =F31*Assumptions!$C$6 -> 1.1516809e+08
B32: Expected aces (count) | C32: ='Build (Monthly)'!AN39 -> 7.6282365 | D32: ='Build (Monthly)'!AO39 -> 42.464771 | E32: ='Build (Monthly)'!AP39 -> 102.48792 | F32: =SUM(C32:E32) -> 152.58093
B33: Expected claims paid | C33: ='Build (Monthly)'!AN40 -> 123958.84 | D33: ='Build (Monthly)'!AO40 -> 690052.52 | E33: ='Build (Monthly)'!AP40 -> 1665428.8 | F33: =SUM(C33:E33) -> 2479440.1 | G33: =F33*Assumptions!$C$6 -> 45869642
B34: Underwriting profit | C34: =C31-C33 -> 187273.21 | D34: =D31-D33 -> 1042510.1 | E34: =E31-E33 -> 2516078.5 | F34: =F31-F33 -> 3745861.8 | G34: =F34*Assumptions!$C$6 -> 69298444
B35: Loss ratio | C35: =C33/C29 -> 0.31862745 | D35: =D33/D29 -> 0.31862745 | E35: =E33/E29 -> 0.31862745 | F35: =F33/F29 -> 0.31862745
B36: Return on premium | C36: =C34/C29 -> 0.48137255 | D36: =D34/D29 -> 0.48137255 | E36: =E34/E29 -> 0.48137255 | F36: =F34/F29 -> 0.48137255
B37: Premium collected per $1 of expected claim | C37: =C29/C33 -> 3.1384615 | D37: =D29/D33 -> 3.1384615 | E37: =E29/E33 -> 3.1384615 | F37: =F29/F33 -> 3.1384615
B39: EXPOSURE PROFILE
B40: Largest single-event exposure (max prize) | C40: =MAX(Assumptions!D35:D39) -> 100000
B41: Average claim per ace | C41: =F33/F32 -> 16250
B42: Total insured swings over 36 months | C42: =F27 -> 1907261.6
B43: Peak monthly premium income | C43: =MAX('Build (Monthly)'!C37:AL37) -> 574447.93
B45: FREQUENCY STRESS TEST — 36-MONTH BASIS
B46: Scenario | C46: Ace frequency multiple | D46: Claims paid | E46: Underwriting profit | F46: Loss ratio | G46: Return on premium | H46: Probability of this or worse
...
